Workbook
Name _Hlk206940199: Sheet2!$F$11
Name adfert_bb_formula: Formula!$B$1:$I$32
Name bb_formula: Formula!$B$1:$I$32
Name kgb: Data!#REF!
Name kgca: Data!#REF!
Name kgcu: Data!#REF!
Name kgfe: Data!#REF!
Name kgk: Data!#REF!
Name kgmg: Data!#REF!
Name kgmn: Data!#REF!
Name kgmo: Data!#REF!
Name kgN: Data!#REF!
Name kgp: Data!#REF!
Name kgs: Data!#REF!
Name kgzn: Data!#REF!
Name lbscl: Data!#REF!
Name lbsk: Data!#REF!
Name lbsmg: Data!#REF!
Name lbsn: Data!#REF!
Name lbsp: Data!#REF!
Name lbss: Data!#REF!
Name rate: Data!#REF!
Name validcustomer: Sheet1!$B$22:$B$37
Name validinco: Sheet1!$B$16:$B$19
Name validpacking: Sheet1!$B$3:$B$12

Sheet Formula
A1: ="Formula "&ROUND(B6,0)&"-"&ROUND(B7,0)&"-"&ROUND(B8,0) -> Formula 10-10-40 | F1: Actual | G1: =B6 -> 10.02004 | H1: =B7 -> 10.02004 | I1: =B8 -> 40.08016 | J1: =B10/100 -> 0.00501002 | K1: MgO | L1: CaO% | M1: =B11 -> 0
A3: Nitrogen Content | F3: Nitrogen Content | K3: K2O | M3: P2O5
A4: Source | B4: Actual | C4: Constrains | F4: Source | G4: Actual | H4: Constrains | K4: 30-0-5 | L4: =(5*B23/B33) -> 0 | M4: MAP | N4: =(61*B25/B33) -> 6.1617827
B5: Content | C5: Min | D5: Max | G5: Content | H5: Min | I5: Max | K5: PN C | L5: =(46*B24/B33) -> 7.4973333 | M5: MKP | N5: =52*B28/B33 -> 3.8582574
A6: %N | B6: =SUMPRODUCT($B$20:$B$31,Data!B10:B21)/B33 -> 10.02004 | C6: 20 | D6: =C6+0.5 -> 20.5 | E6: =IF(OR(B6<C6,B6>D6),"**"," ") -> ** | F6: Urea (NH2) | G6: =(SUMPRODUCT($B$20:$B$31,Data!$B$10:$B$21,Data!M10:M21)/B33)*0.01 -> 0.066075818 | H6: 0 | I6: 1 | K6: MKP | L6: =(34*B28/B33) -> 2.5227068
A7: %P2O5 | B7: =SUMPRODUCT($B$20:$B$31*Data!C10:C21)/B33 -> 10.02004 | C7: 20 | D7: =C7+0.5 -> 20.5 | E7: =IF(OR(B7<C7,B7>D7),"**"," ") -> ** | F7: Amonia (NH4) | G7: =(SUMPRODUCT($B$20:$B$31,Data!$B$10:$B$21,Data!N10:N21)/B33)/100 -> 0.01212154 | H7: 0 | I7: 1 | K7: SOP | L7: =(50*B29/B33) -> 0
A8: %K20 | B8: =SUMPRODUCT($B$20:$B$31*Data!D10:D21)/B33 -> 40.08016 | C8: 20 | D8: =C8+0.5 -> 20.5 | E8: =IF(OR(B8<C8,B8>D8),"**"," ") -> ** | F8: Nitric (NO3) | G8: =(SUMPRODUCT($B$20:$B$31,Data!$B$10:$B$21,Data!O10:O21)/B33)*0.01 -> 0.022003043 | H8: 0 | I8: 1 | K8: KCL | L8: =(60.5*B20/B33) -> 30.310621
A9: %S | B9: =SUMPRODUCT($B$20:$B$31*Data!E10:E21)/B33 -> 0.39140782 | C9: 0 | D9: 100 | E9: =IF(OR(B9<C9,B9>D9),"**"," ") | F9: Total N | G9: =SUM(G6:G8) -> 0.1002004 | K9: Total | L9: =SUM(L4:L8) -> 40.330661 | N9: =SUM(N4:N8) -> 10.02004
A10: %MgO | B10: =SUMPRODUCT($B$20:$B$31*Data!F10:F21)/B33 -> 0.501002 | C10: 1 | D10: 2 | E10: =IF(OR(B10<C10,B10>D10),"**"," ") -> **
A11: CaO | B11: {=SUMPRODUCT($B$20:$B$31*Data!G10:G21)/B33} -> 0 | C11: 0 | D11: 100 | E11: =IF(OR(B11<C11,B11>D11),"**"," ")
B12: =SUMPRODUCT($B$20:$B$31*Data!F12:F23)/B33 -> 3.2324106 | C12: 0 | D12: 100 | E12: =IF(OR(J13<C12,J13>D12),"**"," ") | I12: Solubility | J12: pH | K12: CL % | L12: SO3
A13: e.c.(mS/cm) | B13: =SUMPRODUCT($B$20:$B$31*Data!I10:I21)/B33 -> 1.1721345 | C13: 0 | D13: 100 | E13: =IF(OR(B13<C13,B13>D13),"**"," ") | I13: =SUM(J20:J31) -> 661.10521 | J13: =SUM(I20:I31)/I19 -> 12.138356 | K13: =(B20*0.473)/10 -> 47.3 | L13: =B9*2.5 -> 0.97851954
A15: Raw Material Content
B16: Actual | D16: Constrains | G16: Raw Mat.
B17: Content | D17: Min | E17: Max | G17: Cost
B18: Kg/MT | D18: Kg/MT | E18: Kg/MT | G18: US$/MT
H19: basis | I19: =(1000-B22)/1000 -> 0.71328841
A20: =Data!A10 -> KCL | B20: 1000 | D20: 0 | E20: 0 | G20: 420 | I20: =((8*(B20/1000))*$I$19) -> 5.7063073 | J20: =280*(B20/1000) -> 280
A21: =Data!A11 -> AS | B21: 0 | D21: 0 | E21: 1000 | G21: 400 | I21: =((5*(B21/1000))*$I$19) -> 0 | J21: =180*(B21/1000) -> 0
A22: =Data!A12 -> Urea | B22: 286.71159 | D22: 0 | E22: 1000 | G22: 826 | I22: =((0*(B22/1000))*$I$19) -> 0 | J22: =800*(B22/1000) -> 229.36927
A23: =Data!A13 -> 26-0-0 | B23: 0 | D23: 0 | E23: 0 | G23: 1250 | I23: =((5*(B23/1000))*$I$19) -> 0 | J23: =700*(B23/1000) -> 0
A24: =Data!A14 -> NOP | B24: 325.31907 | D24: 0 | E24: 1000 | G24: 1044 | I24: =((8*(B24/1000))*$I$19) -> 1.8563706 | J24: =180*(B24/1000) -> 58.557433
A25: =Data!A15 -> MAP Tech | B25: 201.62161 | D25: 0 | E25: 1000 | G25: 1140 | I25: =((3.8*(B25/1000))*$I$19) -> 0.54649456 | J25: =240*(B25/1000) -> 48.389187
A26: =Data!A16 -> UP | B26: 0 | D26: 0 | E26: 1000 | G26: 1600 | I26: =((1.2*(B26/1000))*$I$19) -> 0 | J26: =960*(B26/1000) -> 0
A27: =Data!A17 -> MgS | B27: 31.25 | D27: 0 | E27: 1000 | G27: 680 | I27: =((5*(B27/1000))*$I$19) -> 0.11145131 | J27: =0*(B27/1000) -> 0
A28: =Data!A18 -> MKP | B28: 148.09773 | D28: 0 | E28: 1000 | G28: 1958 | I28: =((4*(B28/1000))*$I$19) -> 0.42254557 | J28: =300*(B28/1000) -> 44.429318
A29: =Data!A19 -> SOP C | B29: 0 | D29: 0 | E29: 1000 | G29: 740 | I29: =((3*(B29/1000))*$I$19) -> 0 | J29: =120*(B29/1000) -> 0
A30: T.E | B30: 1 | D30: 5 | E30: 5 | G30: 3754 | I30: =((7*(B30/1000))*$I$19) -> 0.0049930189 | J30: =120*(B30/1000) -> 0.12
A31: Anti Cack. | B31: 2 | D31: 2 | E31: 2 | G31: 1000 | I31: =((7*(B31/1000))*$I$19) -> 0.0099860377 | J31: =120*(B31/1000) -> 0.24
A33: Total | B33: =SUM(B20:B32) -> 1996
H34: =B30 -> 1 | I34: kg TE MIX
B35: 0.71 | E35: EURO | H35: Trace Elements | J35: % | K35: ppm
C36: $ | D36: JD | E36: 1.35 | H36: Boron | J36: =K36/10000 -> 0.0008 | K36: =B30*8 -> 8
A37: Cost | B37: $/MT | C37: {=SUM(G20:G31*B20:B31)/1000} -> 1543.2849 | D37: =C37*$B$35 -> 1095.7323 | E37: =C37/$E$36 -> 1143.174 | H37: CU-EDTA | J37: =K37/10000 -> 0.0026 | K37: =B30*26 -> 26
A38: operation cost | C38: 100 | D38: =C38*$B$35 -> 71 | E38: =C38/$E$36 -> 74.074074 | H38: FE-EDTA | J38: =K38/10000 -> 0.0051 | K38: =B30*51 -> 51
A39: Production Total Cost | C39: =SUM(C37:C38) -> 1643.2849 | D39: =C39*$B$35 -> 1166.7323 | E39: =C39/$E$36 -> 1217.2481 | H39: MN-EDTA | J39: =K39/10000 -> 0.0026 | K39: =B30*26 -> 26
H40: ZN-EDTA | J40: =K40/10000 -> 0.0026 | K40: =B30*26 -> 26
A41: packing (20,25 or 50kg) | C41: 40 | D41: =C41*$B$35 -> 28.4 | E41: =C41/$E$36 -> 29.62963 | F41: 25 kg Bags | H41: Mo. | J41: =K41/10000 -> 5e-05 | K41: =B30*0.5 -> 0.5
A42: pallets | C42: 10 | D42: =C42*$B$35 -> 7.1 | E42: =C42/$E$36 -> 7.4074074
A43: transport | C43: 0 | D43: =C43*$B$35 -> 0 | E43: =C43/$E$36 -> 0 | F43: Ex.work
...

Sheet Data
A5: Raw Materials Nutrient and Price Data Base | M5: Nitrogen Source
A7: Material | B7: %N | C7: %P2O5 | D7: %K20 | E7: %S | F7: %MgO | G7: %CaO | H7: %B | I7: e.c. | M7: Urea | N7: NH4 | O7: NO3
A10: KCL | B10: 0 | C10: 0 | D10: 60 | E10: 0 | F10: 0 | G10: 0 | H10: 0 | I10: 1.6 | N10: 0 | O10: 0 | P10: =IF(AND(B10>0,SUM(M10:O10)<>1),"**","")
A11: AS | B11: 21 | C11: 0 | D11: 0 | E11: 24 | F11: 0 | G11: 0 | H11: 0 | I11: 1.9 | N11: 1 | O11: =1-N11-M11 -> 0 | P11: =IF(AND(B11>0,SUM(M11:O11)<>1),"**","")
A12: Urea | B12: 46 | C12: 0 | D12: 0 | E12: 0 | F12: 0 | G12: 0 | H12: 0 | I12: 0 | M12: 1 | O12: =1-N12-M12 -> 0 | P12: =IF(AND(B12>0,SUM(M12:O12)<>1),"**","")
A13: 26-0-0 | B13: 26 | C13: 0 | D13: 0 | E13: 13 | F13: 0 | G13: 0 | H13: 0 | I13: 1.3 | N13: 0.33 | O13: =1-N13-M13 -> 0.67 | P13: =IF(AND(B13>0,SUM(M13:O13)<>1),"**","")
A14: NOP | B14: 13.5 | C14: 0 | D14: 46 | E14: 0 | F14: 0 | G14: 0 | H14: 0 | I14: 1.23 | N14: 0 | O14: =1-N14-M14 -> 1 | P14: =IF(AND(B14>0,SUM(M14:O14)<>1),"**","")
A15: MAP Tech | B15: 12 | C15: 61 | D15: 0 | E15: 0 | F15: 0 | G15: 0 | H15: 0 | I15: 0.86 | N15: 1 | O15: =1-N15-M15 -> 0 | P15: =IF(AND(B15>0,SUM(M15:O15)<>1),"**","")
A16: UP | B16: 17 | C16: 44 | D16: 0 | E16: 0 | F16: 0 | G16: 0 | H16: 0 | I16: 0.5 | M16: 1 | O16: 0 | P16: =IF(AND(B16>0,SUM(M16:O16)<>1),"**","")
A17: MgS | B17: 0 | C17: 0 | D17: 0 | E17: 25 | F17: 32 | G17: 0 | H17: 0 | I17: 1.9 | P17: =IF(AND(B17>0,SUM(M17:O17)<>1),"**","")
A18: MKP | B18: 0 | C18: 52 | D18: 34 | E18: 0 | F18: 0 | G18: 0 | H18: 0 | I18: 0.7 | P18: =IF(AND(B18>0,SUM(M18:O18)<>1),"**","")
A19: SOP C | B19: 0 | C19: 0 | D19: 50 | E19: 18 | F19: 0 | G19: 0 | H19: 0 | I19: 1.54 | P19: =IF(AND(B19>0,SUM(M19:O19)<>1),"**","")
A20: TE | B20: 0 | C20: 0 | D20: 0 | E20: 0 | F20: 0 | G20: 0 | H20: 0 | I20: 1 | P20: =IF(AND(B20>0,SUM(M20:O20)<>1),"**","")
A21: Anticacking | B21: 0 | C21: 0 | D21: 0 | E21: 0 | F21: 0 | G21: 0 | H21: 0 | I21: 1 | P21: =IF(AND(B21>0,SUM(M21:O21)<>1),"**","")

Sheet 1,2,5kg cost
B4: 1 Kg BAG COST IN USD | G4: Loading Details(For 1kg bag)
B5: =Formula!A1 -> Formula 10-10-40 | C5: Cost($) / Unit | D5: Cost ($) / 1kg bag | G5: No. of pallets / Container | H5: 20 | I5: 110cm * 110 cm
B6: R.M | C6: =Formula!C39 -> 1643.2849 | D6: =C6/1000*1.05 -> 1.7254491 | G6: No. of cartoons (36*36*25)/Pallet | H6: 36 | I6: 3*3*4 = 36
B7: BAG FILM | C7: 6 | D7: =C7/100*1.05 -> 0.063 | G7: No. of (1kg) bags / cartoon | H7: 20 | I7: 20 bag * 1kg
B8: CARTONS | C8: 1 | D8: =C8/20 -> 0.05 | G8: Total No. of bags / pallet | H8: 720 | I8: 36cartoon * 20bag
B9: PALLETS | C9: 15 | D9: =C9/(14/20)/1000 -> 0.021428571 | G9: Total no. of bags / container | H9: 14400 | I9: 720 bag * 20 pallet
B10: OPERATION COST | C10: 100 | D10: =C10/1000 -> 0.1 | G10: Total net weight (Kg)/ container | H10: 14400 | I10: 14400 * 1Kg
B11: TRANSPORTATION | C11: =Formula!B43 -> 0 | D11: =C11/H9 -> 0
B12: Total CFR Cost in ($) | D12: =SUM(D6:D11) -> 1.9598777
B13: Suggested selling price CFR in ($) | D13: =D12/0.5 -> 3.9197554
B14: G.M | D14: =D13-D12 -> 1.9598777
B15: %G.M | D15: =D14/D13 -> 0.5
B18: 2 Kg BAG COST IN USD | G18: Loading Details (For 2kg bag)
B19: =Formula!A1 -> Formula 10-10-40 | C19: Cost($) / Unit | D19: Cost ($) / 1kg bag | G19: No. of pallets / Container | H19: 20 | I19: 110cm * 110 cm
B20: R.M | C20: =Formula!C39 -> 1643.2849 | D20: =C20/500*1.03 -> 3.3851668 | G20: No. of cartoons (36*36*25)/Pallet | H20: 36 | I20: 3*3*4 = 36
B21: BAG FILM | C21: 6 | D21: =C21/60*1.05 -> 0.105 | G21: No. of (2kg) bags / cartoon | H21: 10 | I21: 10 bag * 2kg
B22: CARTONS | C22: 1 | D22: =C22/10 -> 0.1 | G22: Total No. of bags / pallet | H22: 360 | I22: 36cartoon * 10bag
B23: PALLETS | C23: 15 | D23: =C23/(14/20)/500 -> 0.042857143 | G23: Total no. of bags / container | H23: 7200 | I23: 360 bag * 20 pallet
B24: OPERATION COST | C24: 60 | D24: =C24/500 -> 0.12 | G24: Total net weight (Kg)/ container | H24: 14400 | I24: 7200 * 2Kg
B25: TRANSPORTATION | C25: =Formula!B43 -> 0 | D25: =C25/H23 -> 0
B26: Total CFR Cost in ($) | D26: =SUM(D20:D25) -> 3.753024
B27: Suggested selling price CFR in ($) | D27: =D26/0.718 -> 5.2270529
B28: G.M | D28: =D27-D26 -> 1.4740289
B29: %G.M | D29: =D28/D27 -> 0.282
B32: 5 Kg BAG COST IN USD | G32: Loading Details (For 5kg bag)
B33: =Formula!A1 -> Formula 10-10-40 | C33: Cost($) / Unit | D33: Cost ($) / 1kg bag | G33: No. of pallets / Container | H33: 20 | I33: 110cm * 110 cm
B34: R.M | C34: =Formula!C39 -> 1643.2849 | D34: =C34/200*1.015 -> 8.3396707 | G34: No. of cartoons (36*36*25)/Pallet | H34: 36 | I34: 3*3*4 = 36
B35: BAG FILM | C35: 6 | D35: =C35/30*1.05 -> 0.21 | G35: No. of (5kg) bags / cartoon | H35: 4 | I35: 4 bag * 5kg
B36: CARTONS | C36: 1 | D36: =C36/4 -> 0.25 | G36: Total No. of bags / pallet | H36: 144 | I36: 36cartoon * 4bag
B37: PALLETS | C37: 15 | D37: =C37/(14/20)/200 -> 0.10714286 | G37: Total no. of bags / container | H37: 2880 | I37: 144 bag * 20 pallet
B38: OPERATION COST | C38: 50 | D38: =C38/200 -> 0.25 | G38: Total net weight (Kg)/ container | H38: 14400 | I38: 2880 * 5Kg
B39: TRANSPORTATION | C39: =Formula!B43 -> 0 | D39: =C39/H37 -> 0
B40: Total CFR Cost in ($) | D40: =SUM(D34:D39) -> 9.1568136
B41: Suggested selling price CFR in ($) | D41: =D40/0.785 -> 11.664731
B42: G.M | D42: =D41-D40 -> 2.5079171
B43: %G.M | D43: =D42/D41 -> 0.215

Sheet Sheet1
A3: Packing | B3: Formax
B4: Fertinova
B5: Cerbero
B6: farmtic
B7: Other
B8: Tron
B9: Plant Master
B10: Prestige
B11: Hortgreen
B12: Superior
A16: Incoterm | B16: Ex.work
B17: CFR
B18: CPT
B19: FOT
A22: customer | B22: Zarrin
B23: Wakeel
B24: Novagri
B25: Algeria - New
B26: Igna
B27: Tahhan
B28: BlueField
B29: EGR
B30: CRC AFRICA
B31: Tunis - Drzy
B32: Nabat
B33: M. Trade
B34: Eastern
... B37: SAS

Sheet Sheet2
B2: Certificate of Analysis
B4: =" Product Name: "&ROUND(C7,0)&"-"&ROUND(C11,0)&"-"&ROUND(C12,0) -> Product Name: 10-10-40
B6: Elements | C6: % (W/W)
B7: Nitrogen (N) | C7: =SUM(C8:C10) -> 10.02004
B8: NO3 | C8: =Formula!G8*100 -> 2.2003043
B9: NH4 | C9: =Formula!G7*100 -> 1.212154
B10: Urea | C10: =Formula!G6*100 -> 6.6075818
B11: Phosphorus (P2O5) | C11: =Formula!N9 -> 10.02004
B12: Potassium (K2O) | C12: =Formula!L9 -> 40.330661
B13: TE | C13: (W/W)ppm
B14: Fe EDTA | C14: =Formula!K38 -> 51
B15: Zn EDTA | C15: =Formula!K40 -> 26
B16: Mn EDTA | C16: =Formula!K39 -> 26
B17: Cu EDTA | C17: =Formula!K37 -> 26
B18: B | C18: =Formula!K36 -> 8
B19: Heavy metals
B20: Cd | C20: Less than 5 ppm
B21: Cr | C21: Less than 150 ppm
B22: Pb | C22: Less than 150 ppm
B23: As | C23: According to the international standards permitted
B24: Hg
B26: Chloride (Cl) | C26: Less than 1.0 %
B27: Sodium (Na) | C27: Less than 1.0 %
B28: Physical & Chemical Properties
B29: Physical Appearance | C29: Powder
B30: Solubility (5% solu.) | C30: 1
B31: pH (1% solu.) | C31: =Formula!J13 -> 12.138356
